Workbook

Sheet Setup
B2: Negotiate Your Bills Down $200/Month — One Weekend System
B3: Fill in your bills and 4 inputs. The system ranks your top calls and loads the scripts.
B5: YOUR INPUTS — Fill in the yellow cells
B6: Input 3 | C6: Willing to threaten cancellation? | D6: Yes | E6: Yes / Maybe / No — routes you to the stronger or softer script
B7: Input 4 | C7: Have you negotiated bills before? | D7: No | E7: Yes / No / Some of them — affects script detail level
B8: Input 5 | C8: Monthly savings target | D8: 200 | E8: How much do you want back per month? ($50–$300+)
B10: SAVINGS SUMMARY — Auto-calculated from your Bill Audit
C11: Total bills entered | D11: =COUNTA('Bill Audit'!C6:C19) -> 10
C12: Bills marked negotiable | D12: =COUNTIF('Bill Audit'!G6:G19,"Yes") -> 9
C13: Est. total monthly savings | D13: =SUMIF('Bill Audit'!G6:G19,"Yes",'Bill Audit'!F6:F19) -> 23
C14: Est. annual savings | D14: =D13*12 -> 276
C15: Target vs. estimate | D15: =IF(D13=0,"Enter bills in Bill Audit tab",IF(D13>=D8,"ON TRACK — target achievable","GAP: need $"&TEXT(D8-D13,"#,##0")&" more/mo")) -> GAP: need $177 more/mo
B17: HOW TO USE THIS WORKBOOK
B18: Fill in 3 yellow inputs above, then enter your bills in the Bill Audit tab. The system ranks your top calls, loads your scripts, and tracks every dollar you win back.
B20: STEP 1 | C20: Fill in inputs above + enter bills in Bill Audit tab
B21: → | C21: Input 3 — your willingness to threaten cancellation routes you to the stronger or softer script version.
B22: → | C22: Input 4 — negotiation experience determines script detail level (beginner = every word, experienced = condensed).
B23: → | C23: Input 5 — your savings target helps the system tell you how many calls you need to make.
B24: → | C24: Go to the Bill Audit tab and enter every recurring bill: name, provider, current amount, how long you've been a customer.
B25: → | C25: Mark each bill Yes/No in the 'Negotiate?' column — leave No for anything you consider untouchable.
B27: STEP 2 | C27: Check your Prioritized Call List tab — make call #1 this weekend
B28: → | C28: The Prioritized Call List tab ranks your top 5 bills by savings potential × ease of negotiation.
B29: → | C29: Start with the #1 ranked bill — it gives you the most savings for the least effort.
B30: → | C30: Best calling times: Tuesday–Thursday, 10am–2pm. Avoid Mondays and Fridays.
B31: → | C31: Open the Call Scripts tab, find the script for your bill type, and use it during the call.
B32: → | C32: You do not need to read scripts in advance — they're designed to be followed live during the call.
... B46: → | C46: When your monthly savings total hits your Input 5 target — you're done for the weekend.
B49: COLOR LEGEND
B50: Yellow cell | C50: Your input — fill this in
B51: Teal cell | C51: Auto-calculated — do not edit
B52: Amber cell | C52: Action item / tip
B53: Purple cell | C53: Label / category tag
B54: Gray cell | C54: Pre-filled reference data
B55: Green cell | C55: Win logged / savings confirmed
B57: Weekend plan: 2 calls Saturday + 2 calls Sunday = $150–300/mo saved. Average call time: 10–15 minutes.

Sheet Bill Audit
B2: Bill Audit — Enter Every Recurring Bill
B3: List all bills. Mark 'Yes' to negotiate. The system estimates savings and feeds your prioritized call list.
B5: # | C5: Bill / Service Name | D5: Provider (company name) | E5: Monthly Amount | F5: Years w/ Provider | G5: Negotiate? | H5: Est. Savings/Mo | I5: Category | J5: Script Tab
B6: 1 | C6: Internet / Cable | D6: Xfinity | E6: 85 | F6: 3 | G6: Yes | H6: =IF(G6="Yes",27,0) -> 27 | I6: Internet / Cable | J6: Call Scripts
B7: 2 | C7: Cell Phone | D7: Verizon | E7: 95 | F7: 5 | G7: Yes | H7: =IF(G7="Yes",20,0) -> 20 | I7: Cell Phone | J7: Call Scripts
B8: 3 | C8: Car Insurance | D8: State Farm | E8: 180 | F8: 4 | G8: Yes | H8: =IF(G8="Yes",55,0) -> 55 | I8: Car Insurance | J8: Call Scripts
B9: 4 | C9: Home Insurance | D9: Allstate | E9: 120 | F9: 4 | G9: Yes | H9: =IF(G9="Yes",40,0) -> 40 | I9: Home Insurance | J9: Call Scripts
B10: 5 | C10: Streaming Service | D10: Netflix | E10: 18 | F10: 2 | G10: Yes | H10: =IF(G10="Yes",10,0) -> 10 | I10: Streaming Service | J10: Call Scripts
B11: 6 | C11: Gym Membership | D11: Planet Fitness | E11: 25 | F11: 1 | G11: Yes | H11: =IF(G11="Yes",17,0) -> 17 | I11: Gym Membership | J11: Call Scripts
B12: 7 | C12: Credit Card Annual Fee | D12: Chase Sapphire | E12: 95 | F12: 3 | G12: Yes | H12: =IF(G12="Yes",322,0) -> 322 | I12: Credit Card Annual Fee | J12: Call Scripts
B13: 8 | C13: Home Security | D13: ADT | E13: 45 | F13: 2 | G13: No | H13: =IF(G13="Yes",15,0) -> 0 | I13: Home Security | J13: Call Scripts
B14: 9 | C14: Software Subscription | D14: Adobe CC | E14: 55 | F14: 1 | G14: Yes | H14: =IF(G14="Yes",12,0) -> 12 | I14: Software Subscription | J14: Call Scripts
B15: 10 | C15: Medical Bill | D15: City Hospital | E15: 340 | F15: 0 | G15: Yes | H15: =IF(G15="Yes",175,0) -> 175 | I15: Medical Bill | J15: Call Scripts
B16: 11 | H16: =IF(G16="Yes",20,0) -> 0
B17: 12 | H17: =IF(G17="Yes",20,0) -> 0
B18: 13 | H18: =IF(G18="Yes",20,0) -> 0
B19: 14 | H19: =IF(G19="Yes",20,0) -> 0
C20: TOTALS | E20: =SUM(E6:E19) -> 1058 | G20: =COUNTIF(G6:G19,"Yes") -> 9 | H20: =SUM(H6:H19) -> 678
C22: Tip: Enter 'Yes' in Negotiate? for any bill you're willing to call about. Enter 'No' for anything untouchable. The system only estimates savings for Yes bills.

Sheet Prioritized Call List
B2: Prioritized Call List — Your Weekend Battle Plan
B3: Top 5 bills ranked by savings potential. Make these calls first. Estimated savings shown per call.
B5: Rank | C5: Bill Name | D5: Provider | E5: Est. Savings/Mo | F5: Call Time | G5: Difficulty | H5: Script to Use | I5: Weekend
B6: 1 | C6: Internet / Cable | D6: =IFERROR(INDEX('Bill Audit'!D6:D19,MATCH("Internet / Cable",'Bill Audit'!C6:C19,0)),"—") -> Xfinity | E6: =IFERROR(INDEX('Bill Audit'!H6:H19,MATCH("Internet / Cable",'Bill Audit'!C6:C19,0)),"—") -> 27 | F6: 10–15 min | G6: Easy | H6: Internet / Cable | I6: Saturday AM
B7: 2 | C7: Cell Phone | D7: =IFERROR(INDEX('Bill Audit'!D6:D19,MATCH("Cell Phone",'Bill Audit'!C6:C19,0)),"—") -> Verizon | E7: =IFERROR(INDEX('Bill Audit'!H6:H19,MATCH("Cell Phone",'Bill Audit'!C6:C19,0)),"—") -> 20 | F7: 10 min | G7: Easy | H7: Cell Phone | I7: Saturday PM
B8: 3 | C8: Car Insurance | D8: =IFERROR(INDEX('Bill Audit'!D6:D19,MATCH("Car Insurance",'Bill Audit'!C6:C19,0)),"—") -> State Farm | E8: =IFERROR(INDEX('Bill Audit'!H6:H19,MATCH("Car Insurance",'Bill Audit'!C6:C19,0)),"—") -> 55 | F8: 15 min | G8: Medium | H8: Car Insurance | I8: Sunday AM
B9: 4 | C9: Credit Card Annual Fee | D9: =IFERROR(INDEX('Bill Audit'!D6:D19,MATCH("Credit Card Annual Fee",'Bill Audit'!C6:C19,0)),"—") -> Chase Sapphire | E9: =IFERROR(INDEX('Bill Audit'!H6:H19,MATCH("Credit Card Annual Fee",'Bill Audit'!C6:C19,0)),"—") -> 322 | F9: 8 min | G9: Easy | H9: Credit Card Annual Fee | I9: Sunday AM
B10: 5 | C10: Home Insurance | D10: =IFERROR(INDEX('Bill Audit'!D6:D19,MATCH("Home Insurance",'Bill Audit'!C6:C19,0)),"—") -> Allstate | E10: =IFERROR(INDEX('Bill Audit'!H6:H19,MATCH("Home Insurance",'Bill Audit'!C6:C19,0)),"—") -> 40 | F10: 15 min | G10: Medium | H10: Home Insurance | I10: Sunday PM
C11: Est. total if all 5 succeed | E11: =SUM(E6:E10) -> 464 | F11: =E11*12 -> 5568
B13: REMAINING BILLS — Lower priority, call after top 5
B14: 6 | C14: Gym Membership | F14: 5–8 min | G14: Easy | H14: Gym Membership
B15: 7 | C15: Streaming Service | F15: 5 min | G15: Easy | H15: Streaming Service
B16: 8 | C16: Medical Bill | F16: 12 min | G16: Easy | H16: Medical Bill
B17: 9 | C17: Home Security | F17: 10 min | G17: Medium | H17: Home Security
B18: 10 | C18: Software Subscription | F18: 5 min | G18: Easy | H18: Software Subscription
B19: 11 | C19: Lawn / Pest Service | F19: 10 min | G19: Easy | H19: Lawn / Pest Service
B20: 12 | C20: Utility (Electric/Gas) | F20: 12 min | G20: Medium | H20: Utility (Electric/Gas)
B21: 13 | C21: Health Insurance | F21: 20 min | G21: Hard | H21: Health Insurance
B22: 14 | C22: Magazine / News Sub | F22: 5 min | G22: Easy | H22: Magazine / News Sub
C24: Best call times: Tue–Thu, 10am–2pm. Always ask to speak with the retention or loyalty department — they have more authority.

Sheet Call Scripts
B2: Call Scripts — Word for Word
B3: Use during the call. Find your bill type, choose Cancel Leverage or Polite Ask based on Input 3. Read as you go.
B5: Script: Internet / Cable
B6: CANCEL LEVERAGE VERSION (Input 3 = Yes/Maybe)
B7: Before you call | C7: Have ready: account number, current monthly rate, a competitor's current advertised price (Google '[provider] new customer deals' first). Best to call Tuesday–Thursday 10am–2pm.
B8: Opener | C8: "Hi, my name is [your name] and my account number is [number]. I've been a customer for [X years] and I'm currently paying $[amount] per month. I'm reviewing my bills today and I'd like to discuss my rate."
B9: The ask | C9: "I've been looking at current promotions and I'm seeing new customers get [service] for $[competitor price]. I'd like to either match that rate or I'll need to start the cancellation process."
B10: If they say no | C10: "I understand. Can you transfer me to your retention department? I'd prefer to stay but I do need to bring this cost down."
B11: Retention offer | C11: If they offer a new rate: "Can you confirm that's locked in for at least 12 months? And can you note this call in my account?" If yes — take it and log in Win Tracker.
B12: Close | C12: "Thank you. Can you email me confirmation of the new rate? And what's the best number to call if I need to discuss this again in the future?"
B13: POLITE ASK VERSION (Input 3 = No)
B14: Opener | C14: "Hi, I've been a customer for [X years] and I'm reviewing my monthly expenses. I was hoping to discuss whether there are any current promotions or loyalty discounts available on my account."
B15: The ask | C15: "Is there anything you can do to reduce my current monthly rate of $[amount]? Even $10–15 per month would make a real difference."
B16: If they check | C16: "I really appreciate you looking into that. I'm not looking to cancel — I've been happy with the service — I just want to make sure I'm on the best rate available."
B17: Close | C17: "Thank you so much. Can you confirm the new rate in writing? I really appreciate you taking the time."
B19: Script: Cell Phone
B20: CANCEL LEVERAGE VERSION
B21: Before you call | C21: Know your current plan cost, data usage, and a competitor's current deal (T-Mobile and Verizon run promos constantly). Have account number and PIN ready.
B22: Opener | C22: "Hi, account number [X], PIN [X]. I've been a customer for [X years] paying $[amount]/month. I'm comparing plans today and wanted to see what loyalty offers are available before I make a decision."
B23: The ask | C23: "I'm seeing [Competitor] offering [plan] for $[price]. I'd like to stay with you but I need the rate to be competitive. Can you match that or offer something close?"
B24: If they can't | C24: "Can you transfer me to your loyalty team? I'd really prefer to stay — I just need a better rate."
B25: On the new offer | C25: Ask: "Is that price guaranteed for 12 months? Does it require a new contract?" Log any offer in Win Tracker before accepting.
B26: POLITE ASK VERSION
B27: Opener | C27: "Hi, I've been a loyal customer for [X years]. I'm trying to reduce my monthly bills and I was hoping you could check if there are any current promotions or plan adjustments that could lower my $[amount]/month rate."
B28: The ask | C28: "I'm not looking to switch — I've been happy with the service. Is there a loyalty discount or a plan restructure that could save me $10–20 a month?"
B30: Script: Car Insurance
B31: BEST APPROACH: Annual quote shopping
B32: Before you call | C32: Get at least one competing quote first (Progressive, Geico, or a local broker). Even if you don't want to switch, the quote gives you leverage. Have your policy number and current premium ready.
B33: Opener | C33: "Hi, I've been insured with you for [X years] at $[amount]/month. I've been shopping around and I've received a competing quote for less. Before I make any changes, I wanted to give you the opportunity to review my rate."
B34: The ask | C34: "I received a quote for $[amount] from [Competitor] for equivalent coverage. Can you match or beat that rate to keep my business?"
B35: If they say no | C35: "I understand you may not be able to match exactly. Are there any discounts I'm currently not receiving — bundling, safe driver, paperless, paid-in-full? Can you run a full discount review?"
B36: Annual tip | C36: Ask: "When is the best time to call to review my rate for next renewal?" Set a calendar reminder 30 days before renewal — that's when rates are easiest to renegotiate.
B37: Close | C37: "Can you send me a revised quote in writing? I'll review and get back to you within [timeframe]."
B39: Script: Credit Card Annual Fee
B40: ONE CALL — HIGHEST SUCCESS RATE OF ALL 14 BILLS
B41: Before you call | C41: Know your card's annual fee amount, how long you've had the card, and your approximate annual spend on the card. 70–75% success rate — this is the easiest negotiation.
B42: Opener | C42: "Hi, I'm calling about my [card name] account. I just noticed the annual fee of $[amount] posted and I'd like to discuss it."
B43: The ask | C43: "I've been a cardholder for [X years] and I spend approximately $[X]/year on this card. I'm considering whether the fee is worth it for me. Is there anything you can do — waive the fee, offer a statement credit, or reduce it?"
B44: They often say yes immediately | C44: "That's great — can you confirm that credit will post within [X] days? And is this available every year or just this time?"
B45: If they say no | C45: "I understand. Can you transfer me to your retention department? I'd rather keep the card but I need to make the fee worthwhile."
...

Sheet Cancel-Retention Guide
B2: Cancel / Retention Leverage Guide
B3: When to threaten. What to say. How to evaluate an offer on the spot. When to actually follow through.
B5: When to use the cancellation threat
B6: Use it when: | C6: You've been a customer 12+ months and never asked for a discount. Your bill has increased in the last 6–12 months. A competitor has a better rate you can verify online.
B7: Don't use it if: | C7: You just signed a contract with a termination fee. You genuinely can't switch (e.g., only one ISP in your area). You've already used this tactic with this provider in the last 6 months.
B8: The psychology: | C8: Retention departments exist solely to keep customers. They have discount authority the regular billing rep does not. Saying 'cancel' transfers you to where the real deals happen.
B10: Exact phrasing to use
B11: Soft version (Maybe): | C11: "I'm reviewing my bills and I'm considering making some changes. I'd like to explore my options before making a final decision."
B12: Direct version (Yes): | C12: "I'd like to start the cancellation process. I'm not getting value at my current rate and I've found a better option."
B13: Transfer trigger: | C13: "Can you transfer me to your retention/loyalty department? I'd prefer to stay if there's anything that can be done on the rate."
B14: Never say: | C14: "I'm definitely cancelling." — Always leave the door open. The moment you close it, they stop trying to keep you.
B16: How to evaluate a retention offer on the spot
B17: Ask 3 questions: | C17: 1. Is this rate locked for 12 months? 2. Does it require a new contract or commitment? 3. What happens to the rate after the promotional period?
B18: Good offer: | C18: Rate reduction of 15%+ with no new contract and 12-month guarantee. Take it, log it in Win Tracker, set a 11-month reminder to call again.
B19: Medium offer: | C19: Temporary discount (1–3 months free) or one-time credit. Accept only if you can't get a permanent reduction. Ask: 'Is there a permanent rate option too?'
B20: Bad offer: | C20: A new 2-year contract to get a lower rate. Avoid — you lose all future negotiation leverage. Counter: 'I'd prefer the discount without a new commitment.'
B21: No offer at all: | C21: Politely decline and say you'll need to follow through with cancellation. Then call back 48 hours later — different rep = different outcome often.
B23: When to actually cancel
B24: Cancel when: | C24: The competitor is genuinely better and switching is easy. You've called twice and gotten nothing. The service quality doesn't match the price.
B25: Re-sign strategy: | C25: Many providers offer 'win-back' deals to cancelled customers. Cancel → wait 30–60 days → they'll often call with a better deal than any retention offer.
B26: Before you cancel: | C26: Confirm: no early termination fee. No equipment return required (or you know the process). New provider is ready to go on cancellation date.
B27: Log it: | C27: Even cancelled bills go in the Win Tracker. 'Cancelled Netflix $18/mo' = $216/year saved. Every win counts toward your annual total.

Sheet Win Tracker
B2: Win Tracker — Every Dollar Saved, Logged
B3: Log every negotiation result. Running totals calculate automatically. Reuse this every 12 months.
B5: # | C5: Bill / Service | D5: Old Rate/Mo | E5: New Rate/Mo | F5: Savings/Mo | G5: One-Time Win | H5: Call Date | I5: Rep Name | J5: Result | K5: Next Renegotiate
B6: 1 | E6: =IFERROR(IF(C6="","",C6-D6),"") | J6: =IFERROR(IF(G6="","",G6+365),"")
B7: 2 | E7: =IFERROR(IF(C7="","",C7-D7),"") | J7: =IFERROR(IF(G7="","",G7+365),"")
B8: 3 | E8: =IFERROR(IF(C8="","",C8-D8),"") | J8: =IFERROR(IF(G8="","",G8+365),"")
B9: 4 | E9: =IFERROR(IF(C9="","",C9-D9),"") | J9: =IFERROR(IF(G9="","",G9+365),"")
B10: 5 | E10: =IFERROR(IF(C10="","",C10-D10),"") | J10: =IFERROR(IF(G10="","",G10+365),"")
B11: 6 | E11: =IFERROR(IF(C11="","",C11-D11),"") | J11: =IFERROR(IF(G11="","",G11+365),"")
B12: 7 | E12: =IFERROR(IF(C12="","",C12-D12),"") | J12: =IFERROR(IF(G12="","",G12+365),"")
B13: 8 | E13: =IFERROR(IF(C13="","",C13-D13),"") | J13: =IFERROR(IF(G13="","",G13+365),"")
B14: 9 | E14: =IFERROR(IF(C14="","",C14-D14),"") | J14: =IFERROR(IF(G14="","",G14+365),"")
B15: 10 | E15: =IFERROR(IF(C15="","",C15-D15),"") | J15: =IFERROR(IF(G15="","",G15+365),"")
B16: 11 | E16: =IFERROR(IF(C16="","",C16-D16),"") | J16: =IFERROR(IF(G16="","",G16+365),"")
B17: 12 | E17: =IFERROR(IF(C17="","",C17-D17),"") | J17: =IFERROR(IF(G17="","",G17+365),"")
... B20: 15 | E20: =IFERROR(IF(C20="","",C20-D20),"") | J20: =IFERROR(IF(G20="","",G20+365),"")
C21: TOTALS | E21: =SUM(E6:E20) -> 0 | F21: =SUM(F6:F20) -> 0
B23: SAVINGS SUMMARY
C24: Monthly savings secured | D24: =E21 -> 0
C25: Annual savings (×12) | D25: =E21*12 -> 0
C26: One-time wins total | D26: =F21 -> 0
C27: Total year-1 value | D27: =E21*12+F21 -> 0
C28: Calls made | D28: =COUNTA(G6:G20) -> 0
C29: Success rate | D29: =IFERROR(COUNTIF(I6:I20,"Won")/D28,"—") -> —
C31: Result column: enter Won / No Result / Cancelled / Callback Needed. Set calendar reminders from 'Next Renegotiate' column every year.
C33: Next step: Redirect your monthly savings to your Emergency Fund (product 01) or debt payoff (product 02) — or automate it all with product 09.

Sheet Annual Re-Audit
B2: Annual Re-Audit Checklist — Never Overpay Again
B3: Repeat this 5-step process every 12 months. Most bill savings decay — rates creep back without this.
B5: Step | C5: Action | D5: How to do it | E5: Done?
B6: 1 | C6: Open Win Tracker and review 'Next Renegotiate' column | D6: Every bill with a date within the next 30 days is due for a call. Add all of them to your call list for this weekend. Set a recurring annual calendar reminder titled 'Bill Negotiation Weekend.'
B7: 2 | C7: Update the Bill Audit tab with current rates | D7: Log in to each provider's account or check your bank statement. Update the 'Monthly Amount' column with today's actual rate. Rates often creep up $2–5/mo without notice — this is where you catch them.
B8: 3 | C8: Research competitor rates for top 5 bills | D8: Spend 20 minutes Googling '[provider] new customer deals 2025' for each top-5 bill. Screenshot or note any promotional prices. These become your leverage for this year's calls.
B9: 4 | C9: Make your top 5 calls — same scripts, updated amounts | D9: Open the Call Scripts tab. Update the dollar amounts to reflect today's rates. Make the same 5 calls from last year. Providers rotate promotions — what wasn't available last year may be now.
B10: 5 | C10: Log new wins and reset Next Renegotiate dates | D10: Update the Win Tracker with any new savings. The 'Next Renegotiate' column auto-updates 12 months from your new call dates. Your annual savings total resets — track it fresh each year.
C12: Calendar reminder template: Set an annual recurring event titled 'Bill Negotiation Weekend — open 04-negotiate-bills.xlsx and follow re-audit checklist.'
C14: Average person saves $1,800–$3,600/year doing this annually. The system works every year because providers keep raising rates and keep running new promotions.
